Workbook

Sheet Player Details - Post 2025
J1: 2024 | K1: 2025 | L1: 2026 | M1: 2027 | N1: 2028 | O1: 2029 | P1: 2030
A3: Player Name | B3: Franchise | C3: Acq. Date | D3: Drop Date | E3: Contract Type | F3: Salary | G3: Contract Length | H3: Contract Starts | I3: Contract Ends | J3: 2024 Salary Hit | K3: =concatenate(K1, " Salary Hit") -> 2025 Salary Hit | L3: =concatenate(L1, " Salary Hit") -> 2026 Salary Hit | M3: =concatenate(M1, " Salary Hit") -> 2027 Salary Hit | N3: =concatenate(N1, " Salary Hit") -> 2028 Salary Hit | O3: =concatenate(O1, " Salary Hit") -> 2029 Salary Hit | P3: =concatenate(P1, " Salary Hit") -> 2030 Salary Hit
A4: Julio Rodriguez | B4: Brenden Freedman | C4: 45318 | E4: FA Contract | F4: 33100000 | G4: 5 | H4: 2024 | I4: =if(H4="","",if(or($E4="FA Contract",$E4="Dropped"),$H4+$G4-1,if($E4="YP Contract",$H4+2,if(and($E4="Minors",$G4<>"YP"),$H4+$G4-1,if(and($E4="Minors",$G4="YP"),$H4+2,""))))) -> 2028 | J4: 33100000 | K4: =if($E4="","",if($E4="Dropped",if(and(K$1<=$I4,K$1>=$H4),if(Year($D4)=K$1,$F4*0.8,if((year($D4)+1)=K$1,$F4*0.6,$F4*0.4)) ,""),if($E4="Minors",0,if($E4="FA Contract",if(and(K$1<=$I4,K$1>=$H4),$F4,""),if($E4="YP Contract",if(K$1=$H4,500000,if(K$1=($H4+1),1000000,if(K$1=($H4+2),1500000,"")))))))) -> 33100000 | L4: =if($E4="","",if($E4="Dropped",if(and(L$1<=$I4,L$1>=$H4),if(Year($D4)=L$1,$F4*0.8,if((year($D4)+1)=L$1,$F4*0.6,$F4*0.4)) ,""),if($E4="Minors",0,if($E4="FA Contract",if(and(L$1<=$I4,L$1>=$H4),$F4,""),if($E4="YP Contract",if(L$1=$H4,500000,if(L$1=($H4+1),1000000,if(L$1=($H4+2),1500000,"")))))))) -> 33100000 | M4: =if($E4="","",if($E4="Dropped",if(and(M$1<=$I4,M$1>=$H4),if(Year($D4)=M$1,$F4*0.8,if((year($D4)+1)=M$1,$F4*0.6,$F4*0.4)) ,""),if($E4="Minors",0,if($E4="FA Contract",if(and(M$1<=$I4,M$1>=$H4),$F4,""),if($E4="YP Contract",if(M$1=$H4,500000,if(M$1=($H4+1),1000000,if(M$1=($H4+2),1500000,"")))))))) -> 33100000 | N4: =if($E4="","",if($E4="Dropped",if(and(N$1<=$I4,N$1>=$H4),if(Year($D4)=N$1,$F4*0.8,if((year($D4)+1)=N$1,$F4*0.6,$F4*0.4)) ,""),if($E4="Minors",0,if($E4="FA Contract",if(and(N$1<=$I4,N$1>=$H4),$F4,""),if($E4="YP Contract",if(N$1=$H4,500000,if(N$1=($H4+1),1000000,if(N$1=($H4+2),1500000,"")))))))) -> 33100000 | O4: =if($E4="","",if($E4="Dropped",if(and(O$1<=$I4,O$1>=$H4),if(Year($D4)=O$1,$F4*0.8,if((year($D4)+1)=O$1,$F4*0.6,$F4*0.4)) ,""),if($E4="Minors",0,if($E4="FA Contract",if(and(O$1<=$I4,O$1>=$H4),$F4,""),if($E4="YP Contract",if(O$1=$H4,500000,if(O$1=($H4+1),1000000,if(O$1=($H4+2),1500000,"")))))))) | P4: =if($E4="","",if($E4="Dropped",if(and(P$1<=$I4,P$1>=$H4),if(Year($D4)=P$1,$F4*0.8,if((year($D4)+1)=P$1,$F4*0.6,$F4*0.4)) ,""),if($E4="Minors",0,if($E4="FA Contract",if(and(P$1<=$I4,P$1>=$H4),$F4,""),if($E4="YP Contract",if(P$1=$H4,500000,if(P$1=($H4+1),1000000,if(P$1=($H4+2),1500000,""))))))))
A5: Yoshinobu Yamamoto | B5: Brenden Freedman | C5: 45318 | E5: FA Contract | F5: 23800000 | G5: 4 | H5: 2024 | I5: =if(H5="","",if(or($E5="FA Contract",$E5="Dropped"),$H5+$G5-1,if($E5="YP Contract",$H5+2,if(and($E5="Minors",$G5<>"YP"),$H5+$G5-1,if(and($E5="Minors",$G5="YP"),$H5+2,""))))) -> 2027 | J5: 33100000 | K5: =if($E5="","",if($E5="Dropped",if(and(K$1<=$I5,K$1>=$H5),if(Year($D5)=K$1,$F5*0.8,if((year($D5)+1)=K$1,$F5*0.6,$F5*0.4)) ,""),if($E5="Minors",0,if($E5="FA Contract",if(and(K$1<=$I5,K$1>=$H5),$F5,""),if($E5="YP Contract",if(K$1=$H5,500000,if(K$1=($H5+1),1000000,if(K$1=($H5+2),1500000,"")))))))) -> 23800000 | L5: =if($E5="","",if($E5="Dropped",if(and(L$1<=$I5,L$1>=$H5),if(Year($D5)=L$1,$F5*0.8,if((year($D5)+1)=L$1,$F5*0.6,$F5*0.4)) ,""),if($E5="Minors",0,if($E5="FA Contract",if(and(L$1<=$I5,L$1>=$H5),$F5,""),if($E5="YP Contract",if(L$1=$H5,500000,if(L$1=($H5+1),1000000,if(L$1=($H5+2),1500000,"")))))))) -> 23800000 | M5: =if($E5="","",if($E5="Dropped",if(and(M$1<=$I5,M$1>=$H5),if(Year($D5)=M$1,$F5*0.8,if((year($D5)+1)=M$1,$F5*0.6,$F5*0.4)) ,""),if($E5="Minors",0,if($E5="FA Contract",if(and(M$1<=$I5,M$1>=$H5),$F5,""),if($E5="YP Contract",if(M$1=$H5,500000,if(M$1=($H5+1),1000000,if(M$1=($H5+2),1500000,"")))))))) -> 23800000 | N5: =if($E5="","",if($E5="Dropped",if(and(N$1<=$I5,N$1>=$H5),if(Year($D5)=N$1,$F5*0.8,if((year($D5)+1)=N$1,$F5*0.6,$F5*0.4)) ,""),if($E5="Minors",0,if($E5="FA Contract",if(and(N$1<=$I5,N$1>=$H5),$F5,""),if($E5="YP Contract",if(N$1=$H5,500000,if(N$1=($H5+1),1000000,if(N$1=($H5+2),1500000,"")))))))) | O5: =if($E5="","",if($E5="Dropped",if(and(O$1<=$I5,O$1>=$H5),if(Year($D5)=O$1,$F5*0.8,if((year($D5)+1)=O$1,$F5*0.6,$F5*0.4)) ,""),if($E5="Minors",0,if($E5="FA Contract",if(and(O$1<=$I5,O$1>=$H5),$F5,""),if($E5="YP Contract",if(O$1=$H5,500000,if(O$1=($H5+1),1000000,if(O$1=($H5+2),1500000,"")))))))) | P5: =if($E5="","",if($E5="Dropped",if(and(P$1<=$I5,P$1>=$H5),if(Year($D5)=P$1,$F5*0.8,if((year($D5)+1)=P$1,$F5*0.6,$F5*0.4)) ,""),if($E5="Minors",0,if($E5="FA Contract",if(and(P$1<=$I5,P$1>=$H5),$F5,""),if($E5="YP Contract",if(P$1=$H5,500000,if(P$1=($H5+1),1000000,if(P$1=($H5+2),1500000,""))))))))
A6: Jose Ramirez | B6: Brenden Freedman | C6: 45318 | E6: FA Contract | F6: 20000000 | G6: 4 | H6: 2024 | I6: =if(H6="","",if(or($E6="FA Contract",$E6="Dropped"),$H6+$G6-1,if($E6="YP Contract",$H6+2,if(and($E6="Minors",$G6<>"YP"),$H6+$G6-1,if(and($E6="Minors",$G6="YP"),$H6+2,""))))) -> 2027 | J6: 33100000 | K6: =if($E6="","",if($E6="Dropped",if(and(K$1<=$I6,K$1>=$H6),if(Year($D6)=K$1,$F6*0.8,if((year($D6)+1)=K$1,$F6*0.6,$F6*0.4)) ,""),if($E6="Minors",0,if($E6="FA Contract",if(and(K$1<=$I6,K$1>=$H6),$F6,""),if($E6="YP Contract",if(K$1=$H6,500000,if(K$1=($H6+1),1000000,if(K$1=($H6+2),1500000,"")))))))) -> 20000000 | L6: =if($E6="","",if($E6="Dropped",if(and(L$1<=$I6,L$1>=$H6),if(Year($D6)=L$1,$F6*0.8,if((year($D6)+1)=L$1,$F6*0.6,$F6*0.4)) ,""),if($E6="Minors",0,if($E6="FA Contract",if(and(L$1<=$I6,L$1>=$H6),$F6,""),if($E6="YP Contract",if(L$1=$H6,500000,if(L$1=($H6+1),1000000,if(L$1=($H6+2),1500000,"")))))))) -> 20000000 | M6: =if($E6="","",if($E6="Dropped",if(and(M$1<=$I6,M$1>=$H6),if(Year($D6)=M$1,$F6*0.8,if((year($D6)+1)=M$1,$F6*0.6,$F6*0.4)) ,""),if($E6="Minors",0,if($E6="FA Contract",if(and(M$1<=$I6,M$1>=$H6),$F6,""),if($E6="YP Contract",if(M$1=$H6,500000,if(M$1=($H6+1),1000000,if(M$1=($H6+2),1500000,"")))))))) -> 20000000 | N6: =if($E6="","",if($E6="Dropped",if(and(N$1<=$I6,N$1>=$H6),if(Year($D6)=N$1,$F6*0.8,if((year($D6)+1)=N$1,$F6*0.6,$F6*0.4)) ,""),if($E6="Minors",0,if($E6="FA Contract",if(and(N$1<=$I6,N$1>=$H6),$F6,""),if($E6="YP Contract",if(N$1=$H6,500000,if(N$1=($H6+1),1000000,if(N$1=($H6+2),1500000,"")))))))) | O6: =if($E6="","",if($E6="Dropped",if(and(O$1<=$I6,O$1>=$H6),if(Year($D6)=O$1,$F6*0.8,if((year($D6)+1)=O$1,$F6*0.6,$F6*0.4)) ,""),if($E6="Minors",0,if($E6="FA Contract",if(and(O$1<=$I6,O$1>=$H6),$F6,""),if($E6="YP Contract",if(O$1=$H6,500000,if(O$1=($H6+1),1000000,if(O$1=($H6+2),1500000,"")))))))) | P6: =if($E6="","",if($E6="Dropped",if(and(P$1<=$I6,P$1>=$H6),if(Year($D6)=P$1,$F6*0.8,if((year($D6)+1)=P$1,$F6*0.6,$F6*0.4)) ,""),if($E6="Minors",0,if($E6="FA Contract",if(and(P$1<=$I6,P$1>=$H6),$F6,""),if($E6="YP Contract",if(P$1=$H6,500000,if(P$1=($H6+1),1000000,if(P$1=($H6+2),1500000,""))))))))
A7: Kodai Senga | B7: Brenden Freedman | C7: 45318 | E7: FA Contract | F7: 10900000 | G7: 2 | H7: 2024 | I7: =if(H7="","",if(or($E7="FA Contract",$E7="Dropped"),$H7+$G7-1,if($E7="YP Contract",$H7+2,if(and($E7="Minors",$G7<>"YP"),$H7+$G7-1,if(and($E7="Minors",$G7="YP"),$H7+2,""))))) -> 2025 | J7: 33100000 | K7: =if($E7="","",if($E7="Dropped",if(and(K$1<=$I7,K$1>=$H7),if(Year($D7)=K$1,$F7*0.8,if((year($D7)+1)=K$1,$F7*0.6,$F7*0.4)) ,""),if($E7="Minors",0,if($E7="FA Contract",if(and(K$1<=$I7,K$1>=$H7),$F7,""),if($E7="YP Contract",if(K$1=$H7,500000,if(K$1=($H7+1),1000000,if(K$1=($H7+2),1500000,"")))))))) -> 10900000 | L7: =if($E7="","",if($E7="Dropped",if(and(L$1<=$I7,L$1>=$H7),if(Year($D7)=L$1,$F7*0.8,if((year($D7)+1)=L$1,$F7*0.6,$F7*0.4)) ,""),if($E7="Minors",0,if($E7="FA Contract",if(and(L$1<=$I7,L$1>=$H7),$F7,""),if($E7="YP Contract",if(L$1=$H7,500000,if(L$1=($H7+1),1000000,if(L$1=($H7+2),1500000,"")))))))) | M7: =if($E7="","",if($E7="Dropped",if(and(M$1<=$I7,M$1>=$H7),if(Year($D7)=M$1,$F7*0.8,if((year($D7)+1)=M$1,$F7*0.6,$F7*0.4)) ,""),if($E7="Minors",0,if($E7="FA Contract",if(and(M$1<=$I7,M$1>=$H7),$F7,""),if($E7="YP Contract",if(M$1=$H7,500000,if(M$1=($H7+1),1000000,if(M$1=($H7+2),1500000,"")))))))) | N7: =if($E7="","",if($E7="Dropped",if(and(N$1<=$I7,N$1>=$H7),if(Year($D7)=N$1,$F7*0.8,if((year($D7)+1)=N$1,$F7*0.6,$F7*0.4)) ,""),if($E7="Minors",0,if($E7="FA Contract",if(and(N$1<=$I7,N$1>=$H7),$F7,""),if($E7="YP Contract",if(N$1=$H7,500000,if(N$1=($H7+1),1000000,if(N$1=($H7+2),1500000,"")))))))) | O7: =if($E7="","",if($E7="Dropped",if(and(O$1<=$I7,O$1>=$H7),if(Year($D7)=O$1,$F7*0.8,if((year($D7)+1)=O$1,$F7*0.6,$F7*0.4)) ,""),if($E7="Minors",0,if($E7="FA Contract",if(and(O$1<=$I7,O$1>=$H7),$F7,""),if($E7="YP Contract",if(O$1=$H7,500000,if(O$1=($H7+1),1000000,if(O$1=($H7+2),1500000,"")))))))) | P7: =if($E7="","",if($E7="Dropped",if(and(P$1<=$I7,P$1>=$H7),if(Year($D7)=P$1,$F7*0.8,if((year($D7)+1)=P$1,$F7*0.6,$F7*0.4)) ,""),if($E7="Minors",0,if($E7="FA Contract",if(and(P$1<=$I7,P$1>=$H7),$F7,""),if($E7="YP Contract",if(P$1=$H7,500000,if(P$1=($H7+1),1000000,if(P$1=($H7+2),1500000,""))))))))
A8: Cade Smith | B8: Brenden Freedman | C8: 45691 | E8: FA Contract | F8: 6000000 | G8: 3 | H8: 2025 | I8: =if(H8="","",if(or($E8="FA Contract",$E8="Dropped"),$H8+$G8-1,if($E8="YP Contract",$H8+2,if(and($E8="Minors",$G8<>"YP"),$H8+$G8-1,if(and($E8="Minors",$G8="YP"),$H8+2,""))))) -> 2027 | J8: 33100000 | K8: =if($E8="","",if($E8="Dropped",if(and(K$1<=$I8,K$1>=$H8),if(Year($D8)=K$1,$F8*0.8,if((year($D8)+1)=K$1,$F8*0.6,$F8*0.4)) ,""),if($E8="Minors",0,if($E8="FA Contract",if(and(K$1<=$I8,K$1>=$H8),$F8,""),if($E8="YP Contract",if(K$1=$H8,500000,if(K$1=($H8+1),1000000,if(K$1=($H8+2),1500000,"")))))))) -> 6000000 | L8: =if($E8="","",if($E8="Dropped",if(and(L$1<=$I8,L$1>=$H8),if(Year($D8)=L$1,$F8*0.8,if((year($D8)+1)=L$1,$F8*0.6,$F8*0.4)) ,""),if($E8="Minors",0,if($E8="FA Contract",if(and(L$1<=$I8,L$1>=$H8),$F8,""),if($E8="YP Contract",if(L$1=$H8,500000,if(L$1=($H8+1),1000000,if(L$1=($H8+2),1500000,"")))))))) -> 6000000 | M8: =if($E8="","",if($E8="Dropped",if(and(M$1<=$I8,M$1>=$H8),if(Year($D8)=M$1,$F8*0.8,if((year($D8)+1)=M$1,$F8*0.6,$F8*0.4)) ,""),if($E8="Minors",0,if($E8="FA Contract",if(and(M$1<=$I8,M$1>=$H8),$F8,""),if($E8="YP Contract",if(M$1=$H8,500000,if(M$1=($H8+1),1000000,if(M$1=($H8+2),1500000,"")))))))) -> 6000000 | N8: =if($E8="","",if($E8="Dropped",if(and(N$1<=$I8,N$1>=$H8),if(Year($D8)=N$1,$F8*0.8,if((year($D8)+1)=N$1,$F8*0.6,$F8*0.4)) ,""),if($E8="Minors",0,if($E8="FA Contract",if(and(N$1<=$I8,N$1>=$H8),$F8,""),if($E8="YP Contract",if(N$1=$H8,500000,if(N$1=($H8+1),1000000,if(N$1=($H8+2),1500000,"")))))))) | O8: =if($E8="","",if($E8="Dropped",if(and(O$1<=$I8,O$1>=$H8),if(Year($D8)=O$1,$F8*0.8,if((year($D8)+1)=O$1,$F8*0.6,$F8*0.4)) ,""),if($E8="Minors",0,if($E8="FA Contract",if(and(O$1<=$I8,O$1>=$H8),$F8,""),if($E8="YP Contract",if(O$1=$H8,500000,if(O$1=($H8+1),1000000,if(O$1=($H8+2),1500000,"")))))))) | P8: =if($E8="","",if($E8="Dropped",if(and(P$1<=$I8,P$1>=$H8),if(Year($D8)=P$1,$F8*0.8,if((year($D8)+1)=P$1,$F8*0.6,$F8*0.4)) ,""),if($E8="Minors",0,if($E8="FA Contract",if(and(P$1<=$I8,P$1>=$H8),$F8,""),if($E8="YP Contract",if(P$1=$H8,500000,if(P$1=($H8+1),1000000,if(P$1=($H8+2),1500000,""))))))))
A9: George Springer | B9: Brenden Freedman | C9: 45318 | E9: FA Contract | F9: 5100000 | G9: 3 | H9: 2024 | I9: =if(H9="","",if(or($E9="FA Contract",$E9="Dropped"),$H9+$G9-1,if($E9="YP Contract",$H9+2,if(and($E9="Minors",$G9<>"YP"),$H9+$G9-1,if(and($E9="Minors",$G9="YP"),$H9+2,""))))) -> 2026 | J9: 33100000 | K9: =if($E9="","",if($E9="Dropped",if(and(K$1<=$I9,K$1>=$H9),if(Year($D9)=K$1,$F9*0.8,if((year($D9)+1)=K$1,$F9*0.6,$F9*0.4)) ,""),if($E9="Minors",0,if($E9="FA Contract",if(and(K$1<=$I9,K$1>=$H9),$F9,""),if($E9="YP Contract",if(K$1=$H9,500000,if(K$1=($H9+1),1000000,if(K$1=($H9+2),1500000,"")))))))) -> 5100000 | L9: =if($E9="","",if($E9="Dropped",if(and(L$1<=$I9,L$1>=$H9),if(Year($D9)=L$1,$F9*0.8,if((year($D9)+1)=L$1,$F9*0.6,$F9*0.4)) ,""),if($E9="Minors",0,if($E9="FA Contract",if(and(L$1<=$I9,L$1>=$H9),$F9,""),if($E9="YP Contract",if(L$1=$H9,500000,if(L$1=($H9+1),1000000,if(L$1=($H9+2),1500000,"")))))))) -> 5100000 | M9: =if($E9="","",if($E9="Dropped",if(and(M$1<=$I9,M$1>=$H9),if(Year($D9)=M$1,$F9*0.8,if((year($D9)+1)=M$1,$F9*0.6,$F9*0.4)) ,""),if($E9="Minors",0,if($E9="FA Contract",if(and(M$1<=$I9,M$1>=$H9),$F9,""),if($E9="YP Contract",if(M$1=$H9,500000,if(M$1=($H9+1),1000000,if(M$1=($H9+2),1500000,"")))))))) | N9: =if($E9="","",if($E9="Dropped",if(and(N$1<=$I9,N$1>=$H9),if(Year($D9)=N$1,$F9*0.8,if((year($D9)+1)=N$1,$F9*0.6,$F9*0.4)) ,""),if($E9="Minors",0,if($E9="FA Contract",if(and(N$1<=$I9,N$1>=$H9),$F9,""),if($E9="YP Contract",if(N$1=$H9,500000,if(N$1=($H9+1),1000000,if(N$1=($H9+2),1500000,"")))))))) | O9: =if($E9="","",if($E9="Dropped",if(and(O$1<=$I9,O$1>=$H9),if(Year($D9)=O$1,$F9*0.8,if((year($D9)+1)=O$1,$F9*0.6,$F9*0.4)) ,""),if($E9="Minors",0,if($E9="FA Contract",if(and(O$1<=$I9,O$1>=$H9),$F9,""),if($E9="YP Contract",if(O$1=$H9,500000,if(O$1=($H9+1),1000000,if(O$1=($H9+2),1500000,"")))))))) | P9: =if($E9="","",if($E9="Dropped",if(and(P$1<=$I9,P$1>=$H9),if(Year($D9)=P$1,$F9*0.8,if((year($D9)+1)=P$1,$F9*0.6,$F9*0.4)) ,""),if($E9="Minors",0,if($E9="FA Contract",if(and(P$1<=$I9,P$1>=$H9),$F9,""),if($E9="YP Contract",if(P$1=$H9,500000,if(P$1=($H9+1),1000000,if(P$1=($H9+2),1500000,""))))))))
A10: JT Realmuto | B10: Brenden Freedman | C10: 45356 | E10: FA Contract | F10: 5000000 | G10: 2 | H10: 2024 | I10: =if(H10="","",if(or($E10="FA Contract",$E10="Dropped"),$H10+$G10-1,if($E10="YP Contract",$H10+2,if(and($E10="Minors",$G10<>"YP"),$H10+$G10-1,if(and($E10="Minors",$G10="YP"),$H10+2,""))))) -> 2025 | J10: 33100000 | K10: =if($E10="","",if($E10="Dropped",if(and(K$1<=$I10,K$1>=$H10),if(Year($D10)=K$1,$F10*0.8,if((year($D10)+1)=K$1,$F10*0.6,$F10*0.4)) ,""),if($E10="Minors",0,if($E10="FA Contract",if(and(K$1<=$I10,K$1>=$H10),$F10,""),if($E10="YP Contract",if(K$1=$H10,500000,if(K$1=($H10+1),1000000,if(K$1=($H10+2),1500000,"")))))))) -> 5000000 | L10: =if($E10="","",if($E10="Dropped",if(and(L$1<=$I10,L$1>=$H10),if(Year($D10)=L$1,$F10*0.8,if((year($D10)+1)=L$1,$F10*0.6,$F10*0.4)) ,""),if($E10="Minors",0,if($E10="FA Contract",if(and(L$1<=$I10,L$1>=$H10),$F10,""),if($E10="YP Contract",if(L$1=$H10,500000,if(L$1=($H10+1),1000000,if(L$1=($H10+2),1500000,"")))))))) | M10: =if($E10="","",if($E10="Dropped",if(and(M$1<=$I10,M$1>=$H10),if(Year($D10)=M$1,$F10*0.8,if((year($D10)+1)=M$1,$F10*0.6,$F10*0.4)) ,""),if($E10="Minors",0,if($E10="FA Contract",if(and(M$1<=$I10,M$1>=$H10),$F10,""),if($E10="YP Contract",if(M$1=$H10,500000,if(M$1=($H10+1),1000000,if(M$1=($H10+2),1500000,"")))))))) | N10: =if($E10="","",if($E10="Dropped",if(and(N$1<=$I10,N$1>=$H10),if(Year($D10)=N$1,$F10*0.8,if((year($D10)+1)=N$1,$F10*0.6,$F10*0.4)) ,""),if($E10="Minors",0,if($E10="FA Contract",if(and(N$1<=$I10,N$1>=$H10),$F10,""),if($E10="YP Contract",if(N$1=$H10,500000,if(N$1=($H10+1),1000000,if(N$1=($H10+2),1500000,"")))))))) | O10: =if($E10="","",if($E10="Dropped",if(and(O$1<=$I10,O$1>=$H10),if(Year($D10)=O$1,$F10*0.8,if((year($D10)+1)=O$1,$F10*0.6,$F10*0.4)) ,""),if($E10="Minors",0,if($E10="FA Contract",if(and(O$1<=$I10,O$1>=$H10),$F10,""),if($E10="YP Contract",if(O$1=$H10,500000,if(O$1=($H10+1),1000000,if(O$1=($H10+2),1500000,"")))))))) | P10: =if($E10="","",if($E10="Dropped",if(and(P$1<=$I10,P$1>=$H10),if(Year($D10)=P$1,$F10*0.8,if((year($D10)+1)=P$1,$F10*0.6,$F10*0.4)) ,""),if($E10="Minors",0,if($E10="FA Contract",if(and(P$1<=$I10,P$1>=$H10),$F10,""),if($E10="YP Contract",if(P$1=$H10,500000,if(P$1=($H10+1),1000000,if(P$1=($H10+2),1500000,""))))))))
A11: Nathaniel Lowe | B11: Brenden Freedman | C11: 45356 | E11: FA Contract | F11: 5000000 | G11: 2 | H11: 2024 | I11: =if(H11="","",if(or($E11="FA Contract",$E11="Dropped"),$H11+$G11-1,if($E11="YP Contract",$H11+2,if(and($E11="Minors",$G11<>"YP"),$H11+$G11-1,if(and($E11="Minors",$G11="YP"),$H11+2,""))))) -> 2025 | J11: 33100000 | K11: =if($E11="","",if($E11="Dropped",if(and(K$1<=$I11,K$1>=$H11),if(Year($D11)=K$1,$F11*0.8,if((year($D11)+1)=K$1,$F11*0.6,$F11*0.4)) ,""),if($E11="Minors",0,if($E11="FA Contract",if(and(K$1<=$I11,K$1>=$H11),$F11,""),if($E11="YP Contract",if(K$1=$H11,500000,if(K$1=($H11+1),1000000,if(K$1=($H11+2),1500000,"")))))))) -> 5000000 | L11: =if($E11="","",if($E11="Dropped",if(and(L$1<=$I11,L$1>=$H11),if(Year($D11)=L$1,$F11*0.8,if((year($D11)+1)=L$1,$F11*0.6,$F11*0.4)) ,""),if($E11="Minors",0,if($E11="FA Contract",if(and(L$1<=$I11,L$1>=$H11),$F11,""),if($E11="YP Contract",if(L$1=$H11,500000,if(L$1=($H11+1),1000000,if(L$1=($H11+2),1500000,"")))))))) | M11: =if($E11="","",if($E11="Dropped",if(and(M$1<=$I11,M$1>=$H11),if(Year($D11)=M$1,$F11*0.8,if((year($D11)+1)=M$1,$F11*0.6,$F11*0.4)) ,""),if($E11="Minors",0,if($E11="FA Contract",if(and(M$1<=$I11,M$1>=$H11),$F11,""),if($E11="YP Contract",if(M$1=$H11,500000,if(M$1=($H11+1),1000000,if(M$1=($H11+2),1500000,"")))))))) | N11: =if($E11="","",if($E11="Dropped",if(and(N$1<=$I11,N$1>=$H11),if(Year($D11)=N$1,$F11*0.8,if((year($D11)+1)=N$1,$F11*0.6,$F11*0.4)) ,""),if($E11="Minors",0,if($E11="FA Contract",if(and(N$1<=$I11,N$1>=$H11),$F11,""),if($E11="YP Contract",if(N$1=$H11,500000,if(N$1=($H11+1),1000000,if(N$1=($H11+2),1500000,"")))))))) | O11: =if($E11="","",if($E11="Dropped",if(and(O$1<=$I11,O$1>=$H11),if(Year($D11)=O$1,$F11*0.8,if((year($D11)+1)=O$1,$F11*0.6,$F11*0.4)) ,""),if($E11="Minors",0,if($E11="FA Contract",if(and(O$1<=$I11,O$1>=$H11),$F11,""),if($E11="YP Contract",if(O$1=$H11,500000,if(O$1=($H11+1),1000000,if(O$1=($H11+2),1500000,"")))))))) | P11: =if($E11="","",if($E11="Dropped",if(and(P$1<=$I11,P$1>=$H11),if(Year($D11)=P$1,$F11*0.8,if((year($D11)+1)=P$1,$F11*0.6,$F11*0.4)) ,""),if($E11="Minors",0,if($E11="FA Contract",if(and(P$1<=$I11,P$1>=$H11),$F11,""),if($E11="YP Contract",if(P$1=$H11,500000,if(P$1=($H11+1),1000000,if(P$1=($H11+2),1500000,""))))))))
A12: Ronel Blanco | B12: Brenden Freedman | C12: 45721 | E12: FA Contract | F12: 5000000 | G12: 2 | H12: 2025 | I12: =if(H12="","",if(or($E12="FA Contract",$E12="Dropped"),$H12+$G12-1,if($E12="YP Contract",$H12+2,if(and($E12="Minors",$G12<>"YP"),$H12+$G12-1,if(and($E12="Minors",$G12="YP"),$H12+2,""))))) -> 2026 | J12: 33100000 | K12: =if($E12="","",if($E12="Dropped",if(and(K$1<=$I12,K$1>=$H12),if(Year($D12)=K$1,$F12*0.8,if((year($D12)+1)=K$1,$F12*0.6,$F12*0.4)) ,""),if($E12="Minors",0,if($E12="FA Contract",if(and(K$1<=$I12,K$1>=$H12),$F12,""),if($E12="YP Contract",if(K$1=$H12,500000,if(K$1=($H12+1),1000000,if(K$1=($H12+2),1500000,"")))))))) -> 5000000 | L12: =if($E12="","",if($E12="Dropped",if(and(L$1<=$I12,L$1>=$H12),if(Year($D12)=L$1,$F12*0.8,if((year($D12)+1)=L$1,$F12*0.6,$F12*0.4)) ,""),if($E12="Minors",0,if($E12="FA Contract",if(and(L$1<=$I12,L$1>=$H12),$F12,""),if($E12="YP Contract",if(L$1=$H12,500000,if(L$1=($H12+1),1000000,if(L$1=($H12+2),1500000,"")))))))) -> 5000000 | M12: =if($E12="","",if($E12="Dropped",if(and(M$1<=$I12,M$1>=$H12),if(Year($D12)=M$1,$F12*0.8,if((year($D12)+1)=M$1,$F12*0.6,$F12*0.4)) ,""),if($E12="Minors",0,if($E12="FA Contract",if(and(M$1<=$I12,M$1>=$H12),$F12,""),if($E12="YP Contract",if(M$1=$H12,500000,if(M$1=($H12+1),1000000,if(M$1=($H12+2),1500000,"")))))))) | N12: =if($E12="","",if($E12="Dropped",if(and(N$1<=$I12,N$1>=$H12),if(Year($D12)=N$1,$F12*0.8,if((year($D12)+1)=N$1,$F12*0.6,$F12*0.4)) ,""),if($E12="Minors",0,if($E12="FA Contract",if(and(N$1<=$I12,N$1>=$H12),$F12,""),if($E12="YP Contract",if(N$1=$H12,500000,if(N$1=($H12+1),1000000,if(N$1=($H12+2),1500000,"")))))))) | O12: =if($E12="","",if($E12="Dropped",if(and(O$1<=$I12,O$1>=$H12),if(Year($D12)=O$1,$F12*0.8,if((year($D12)+1)=O$1,$F12*0.6,$F12*0.4)) ,""),if($E12="Minors",0,if($E12="FA Contract",if(and(O$1<=$I12,O$1>=$H12),$F12,""),if($E12="YP Contract",if(O$1=$H12,500000,if(O$1=($H12+1),1000000,if(O$1=($H12+2),1500000,"")))))))) | P12: =if($E12="","",if($E12="Dropped",if(and(P$1<=$I12,P$1>=$H12),if(Year($D12)=P$1,$F12*0.8,if((year($D12)+1)=P$1,$F12*0.6,$F12*0.4)) ,""),if($E12="Minors",0,if($E12="FA Contract",if(and(P$1<=$I12,P$1>=$H12),$F12,""),if($E12="YP Contract",if(P$1=$H12,500000,if(P$1=($H12+1),1000000,if(P$1=($H12+2),1500000,""))))))))
A13: Dansby Swanson | B13: Brenden Freedman | C13: 45318 | E13: FA Contract | F13: 4600000 | G13: 3 | H13: 2024 | I13: =if(H13="","",if(or($E13="FA Contract",$E13="Dropped"),$H13+$G13-1,if($E13="YP Contract",$H13+2,if(and($E13="Minors",$G13<>"YP"),$H13+$G13-1,if(and($E13="Minors",$G13="YP"),$H13+2,""))))) -> 2026 | J13: 33100000 | K13: =if($E13="","",if($E13="Dropped",if(and(K$1<=$I13,K$1>=$H13),if(Year($D13)=K$1,$F13*0.8,if((year($D13)+1)=K$1,$F13*0.6,$F13*0.4)) ,""),if($E13="Minors",0,if($E13="FA Contract",if(and(K$1<=$I13,K$1>=$H13),$F13,""),if($E13="YP Contract",if(K$1=$H13,500000,if(K$1=($H13+1),1000000,if(K$1=($H13+2),1500000,"")))))))) -> 4600000 | L13: =if($E13="","",if($E13="Dropped",if(and(L$1<=$I13,L$1>=$H13),if(Year($D13)=L$1,$F13*0.8,if((year($D13)+1)=L$1,$F13*0.6,$F13*0.4)) ,""),if($E13="Minors",0,if($E13="FA Contract",if(and(L$1<=$I13,L$1>=$H13),$F13,""),if($E13="YP Contract",if(L$1=$H13,500000,if(L$1=($H13+1),1000000,if(L$1=($H13+2),1500000,"")))))))) -> 4600000 | M13: =if($E13="","",if($E13="Dropped",if(and(M$1<=$I13,M$1>=$H13),if(Year($D13)=M$1,$F13*0.8,if((year($D13)+1)=M$1,$F13*0.6,$F13*0.4)) ,""),if($E13="Minors",0,if($E13="FA Contract",if(and(M$1<=$I13,M$1>=$H13),$F13,""),if($E13="YP Contract",if(M$1=$H13,500000,if(M$1=($H13+1),1000000,if(M$1=($H13+2),1500000,"")))))))) | N13: =if($E13="","",if($E13="Dropped",if(and(N$1<=$I13,N$1>=$H13),if(Year($D13)=N$1,$F13*0.8,if((year($D13)+1)=N$1,$F13*0.6,$F13*0.4)) ,""),if($E13="Minors",0,if($E13="FA Contract",if(and(N$1<=$I13,N$1>=$H13),$F13,""),if($E13="YP Contract",if(N$1=$H13,500000,if(N$1=($H13+1),1000000,if(N$1=($H13+2),1500000,"")))))))) | O13: =if($E13="","",if($E13="Dropped",if(and(O$1<=$I13,O$1>=$H13),if(Year($D13)=O$1,$F13*0.8,if((year($D13)+1)=O$1,$F13*0.6,$F13*0.4)) ,""),if($E13="Minors",0,if($E13="FA Contract",if(and(O$1<=$I13,O$1>=$H13),$F13,""),if($E13="YP Contract",if(O$1=$H13,500000,if(O$1=($H13+1),1000000,if(O$1=($H13+2),1500000,"")))))))) | P13: =if($E13="","",if($E13="Dropped",if(and(P$1<=$I13,P$1>=$H13),if(Year($D13)=P$1,$F13*0.8,if((year($D13)+1)=P$1,$F13*0.6,$F13*0.4)) ,""),if($E13="Minors",0,if($E13="FA Contract",if(and(P$1<=$I13,P$1>=$H13),$F13,""),if($E13="YP Contract",if(P$1=$H13,500000,if(P$1=($H13+1),1000000,if(P$1=($H13+2),1500000,""))))))))
A14: Dean Kremer | B14: Brenden Freedman | C14: 45356 | E14: FA Contract | F14: 4000000 | G14: 2 | H14: 2024 | I14: =if(H14="","",if(or($E14="FA Contract",$E14="Dropped"),$H14+$G14-1,if($E14="YP Contract",$H14+2,if(and($E14="Minors",$G14<>"YP"),$H14+$G14-1,if(and($E14="Minors",$G14="YP"),$H14+2,""))))) -> 2025 | J14: 33100000 | K14: =if($E14="","",if($E14="Dropped",if(and(K$1<=$I14,K$1>=$H14),if(Year($D14)=K$1,$F14*0.8,if((year($D14)+1)=K$1,$F14*0.6,$F14*0.4)) ,""),if($E14="Minors",0,if($E14="FA Contract",if(and(K$1<=$I14,K$1>=$H14),$F14,""),if($E14="YP Contract",if(K$1=$H14,500000,if(K$1=($H14+1),1000000,if(K$1=($H14+2),1500000,"")))))))) -> 4000000 | L14: =if($E14="","",if($E14="Dropped",if(and(L$1<=$I14,L$1>=$H14),if(Year($D14)=L$1,$F14*0.8,if((year($D14)+1)=L$1,$F14*0.6,$F14*0.4)) ,""),if($E14="Minors",0,if($E14="FA Contract",if(and(L$1<=$I14,L$1>=$H14),$F14,""),if($E14="YP Contract",if(L$1=$H14,500000,if(L$1=($H14+1),1000000,if(L$1=($H14+2),1500000,"")))))))) | M14: =if($E14="","",if($E14="Dropped",if(and(M$1<=$I14,M$1>=$H14),if(Year($D14)=M$1,$F14*0.8,if((year($D14)+1)=M$1,$F14*0.6,$F14*0.4)) ,""),if($E14="Minors",0,if($E14="FA Contract",if(and(M$1<=$I14,M$1>=$H14),$F14,""),if($E14="YP Contract",if(M$1=$H14,500000,if(M$1=($H14+1),1000000,if(M$1=($H14+2),1500000,"")))))))) | N14: =if($E14="","",if($E14="Dropped",if(and(N$1<=$I14,N$1>=$H14),if(Year($D14)=N$1,$F14*0.8,if((year($D14)+1)=N$1,$F14*0.6,$F14*0.4)) ,""),if($E14="Minors",0,if($E14="FA Contract",if(and(N$1<=$I14,N$1>=$H14),$F14,""),if($E14="YP Contract",if(N$1=$H14,500000,if(N$1=($H14+1),1000000,if(N$1=($H14+2),1500000,"")))))))) | O14: =if($E14="","",if($E14="Dropped",if(and(O$1<=$I14,O$1>=$H14),if(Year($D14)=O$1,$F14*0.8,if((year($D14)+1)=O$1,$F14*0.6,$F14*0.4)) ,""),if($E14="Minors",0,if($E14="FA Contract",if(and(O$1<=$I14,O$1>=$H14),$F14,""),if($E14="YP Contract",if(O$1=$H14,500000,if(O$1=($H14+1),1000000,if(O$1=($H14+2),1500000,"")))))))) | P14: =if($E14="","",if($E14="Dropped",if(and(P$1<=$I14,P$1>=$H14),if(Year($D14)=P$1,$F14*0.8,if((year($D14)+1)=P$1,$F14*0.6,$F14*0.4)) ,""),if($E14="Minors",0,if($E14="FA Contract",if(and(P$1<=$I14,P$1>=$H14),$F14,""),if($E14="YP Contract",if(P$1=$H14,500000,if(P$1=($H14+1),1000000,if(P$1=($H14+2),1500000,""))))))))
A15: Craig Kimbrel | B15: Brenden Freedman | C15: 45356 | E15: FA Contract | F15: 3000000 | G15: 2 | H15: 2024 | I15: =if(H15="","",if(or($E15="FA Contract",$E15="Dropped"),$H15+$G15-1,if($E15="YP Contract",$H15+2,if(and($E15="Minors",$G15<>"YP"),$H15+$G15-1,if(and($E15="Minors",$G15="YP"),$H15+2,""))))) -> 2025 | J15: 33100000 | K15: =if($E15="","",if($E15="Dropped",if(and(K$1<=$I15,K$1>=$H15),if(Year($D15)=K$1,$F15*0.8,if((year($D15)+1)=K$1,$F15*0.6,$F15*0.4)) ,""),if($E15="Minors",0,if($E15="FA Contract",if(and(K$1<=$I15,K$1>=$H15),$F15,""),if($E15="YP Contract",if(K$1=$H15,500000,if(K$1=($H15+1),1000000,if(K$1=($H15+2),1500000,"")))))))) -> 3000000 | L15: =if($E15="","",if($E15="Dropped",if(and(L$1<=$I15,L$1>=$H15),if(Year($D15)=L$1,$F15*0.8,if((year($D15)+1)=L$1,$F15*0.6,$F15*0.4)) ,""),if($E15="Minors",0,if($E15="FA Contract",if(and(L$1<=$I15,L$1>=$H15),$F15,""),if($E15="YP Contract",if(L$1=$H15,500000,if(L$1=($H15+1),1000000,if(L$1=($H15+2),1500000,"")))))))) | M15: =if($E15="","",if($E15="Dropped",if(and(M$1<=$I15,M$1>=$H15),if(Year($D15)=M$1,$F15*0.8,if((year($D15)+1)=M$1,$F15*0.6,$F15*0.4)) ,""),if($E15="Minors",0,if($E15="FA Contract",if(and(M$1<=$I15,M$1>=$H15),$F15,""),if($E15="YP Contract",if(M$1=$H15,500000,if(M$1=($H15+1),1000000,if(M$1=($H15+2),1500000,"")))))))) | N15: =if($E15="","",if($E15="Dropped",if(and(N$1<=$I15,N$1>=$H15),if(Year($D15)=N$1,$F15*0.8,if((year($D15)+1)=N$1,$F15*0.6,$F15*0.4)) ,""),if($E15="Minors",0,if($E15="FA Contract",if(and(N$1<=$I15,N$1>=$H15),$F15,""),if($E15="YP Contract",if(N$1=$H15,500000,if(N$1=($H15+1),1000000,if(N$1=($H15+2),1500000,"")))))))) | O15: =if($E15="","",if($E15="Dropped",if(and(O$1<=$I15,O$1>=$H15),if(Year($D15)=O$1,$F15*0.8,if((year($D15)+1)=O$1,$F15*0.6,$F15*0.4)) ,""),if($E15="Minors",0,if($E15="FA Contract",if(and(O$1<=$I15,O$1>=$H15),$F15,""),if($E15="YP Contract",if(O$1=$H15,500000,if(O$1=($H15+1),1000000,if(O$1=($H15+2),1500000,"")))))))) | P15: =if($E15="","",if($E15="Dropped",if(and(P$1<=$I15,P$1>=$H15),if(Year($D15)=P$1,$F15*0.8,if((year($D15)+1)=P$1,$F15*0.6,$F15*0.4)) ,""),if($E15="Minors",0,if($E15="FA Contract",if(and(P$1<=$I15,P$1>=$H15),$F15,""),if($E15="YP Contract",if(P$1=$H15,500000,if(P$1=($H15+1),1000000,if(P$1=($H15+2),1500000,""))))))))
... A20: Triston McKenzie | B20: Brenden Freedman | C20: 45318 | E20: FA Contract | F20: 2000000 | G20: 2 | H20: 2024 | I20: =if(H20="","",if(or($E20="FA Contract",$E20="Dropped"),$H20+$G20-1,if($E20="YP Contract",$H20+2,if(and($E20="Minors",$G20<>"YP"),$H20+$G20-1,if(and($E20="Minors",$G20="YP"),$H20+2,""))))) -> 2025 | J20: 33100000 | K20: =if($E20="","",if($E20="Dropped",if(and(K$1<=$I20,K$1>=$H20),if(Year($D20)=K$1,$F20*0.8,if((year($D20)+1)=K$1,$F20*0.6,$F20*0.4)) ,""),if($E20="Minors",0,if($E20="FA Contract",if(and(K$1<=$I20,K$1>=$H20),$F20,""),if($E20="YP Contract",if(K$1=$H20,500000,if(K$1=($H20+1),1000000,if(K$1=($H20+2),1500000,"")))))))) -> 2000000 | L20: =if($E20="","",if($E20="Dropped",if(and(L$1<=$I20,L$1>=$H20),if(Year($D20)=L$1,$F20*0.8,if((year($D20)+1)=L$1,$F20*0.6,$F20*0.4)) ,""),if($E20="Minors",0,if($E20="FA Contract",if(and(L$1<=$I20,L$1>=$H20),$F20,""),if($E20="YP Contract",if(L$1=$H20,500000,if(L$1=($H20+1),1000000,if(L$1=($H20+2),1500000,"")))))))) | M20: =if($E20="","",if($E20="Dropped",if(and(M$1<=$I20,M$1>=$H20),if(Year($D20)=M$1,$F20*0.8,if((year($D20)+1)=M$1,$F20*0.6,$F20*0.4)) ,""),if($E20="Minors",0,if($E20="FA Contract",if(and(M$1<=$I20,M$1>=$H20),$F20,""),if($E20="YP Contract",if(M$1=$H20,500000,if(M$1=($H20+1),1000000,if(M$1=($H20+2),1500000,"")))))))) | N20: =if($E20="","",if($E20="Dropped",if(and(N$1<=$I20,N$1>=$H20),if(Year($D20)=N$1,$F20*0.8,if((year($D20)+1)=N$1,$F20*0.6,$F20*0.4)) ,""),if($E20="Minors",0,if($E20="FA Contract",if(and(N$1<=$I20,N$1>=$H20),$F20,""),if($E20="YP Contract",if(N$1=$H20,500000,if(N$1=($H20+1),1000000,if(N$1=($H20+2),1500000,"")))))))) | O20: =if($E20="","",if($E20="Dropped",if(and(O$1<=$I20,O$1>=$H20),if(Year($D20)=O$1,$F20*0.8,if((year($D20)+1)=O$1,$F20*0.6,$F20*0.4)) ,""),if($E20="Minors",0,if($E20="FA Contract",if(and(O$1<=$I20,O$1>=$H20),$F20,""),if($E20="YP Contract",if(O$1=$H20,500000,if(O$1=($H20+1),1000000,if(O$1=($H20+2),1500000,"")))))))) | P20: =if($E20="","",if($E20="Dropped",if(and(P$1<=$I20,P$1>=$H20),if(Year($D20)=P$1,$F20*0.8,if((year($D20)+1)=P$1,$F20*0.6,$F20*0.4)) ,""),if($E20="Minors",0,if($E20="FA Contract",if(and(P$1<=$I20,P$1>=$H20),$F20,""),if($E20="YP Contract",if(P$1=$H20,500000,if(P$1=($H20+1),1000000,if(P$1=($H20+2),1500000,""))))))))
A21: Whitt Merrifield | B21: Brenden Freedman | C21: 45356 | D21: 45761 | E21: Dropped | F21: 2500000 | G21: 2 | H21: 2024 | I21: =if(H21="","",if(or($E21="FA Contract",$E21="Dropped"),$H21+$G21-1,if($E21="YP Contract",$H21+2,if(and($E21="Minors",$G21<>"YP"),$H21+$G21-1,if(and($E21="Minors",$G21="YP"),$H21+2,""))))) -> 2025 | J21: 33100000 | K21: =if($E21="","",if($E21="Dropped",if(and(K$1<=$I21,K$1>=$H21),if(Year($D21)=K$1,$F21*0.8,if((year($D21)+1)=K$1,$F21*0.6,$F21*0.4)) ,""),if($E21="Minors",0,if($E21="FA Contract",if(and(K$1<=$I21,K$1>=$H21),$F21,""),if($E21="YP Contract",if(K$1=$H21,500000,if(K$1=($H21+1),1000000,if(K$1=($H21+2),1500000,"")))))))) -> 2000000 | L21: =if($E21="","",if($E21="Dropped",if(and(L$1<=$I21,L$1>=$H21),if(Year($D21)=L$1,$F21*0.8,if((year($D21)+1)=L$1,$F21*0.6,$F21*0.4)) ,""),if($E21="Minors",0,if($E21="FA Contract",if(and(L$1<=$I21,L$1>=$H21),$F21,""),if($E21="YP Contract",if(L$1=$H21,500000,if(L$1=($H21+1),1000000,if(L$1=($H21+2),1500000,"")))))))) | M21: =if($E21="","",if($E21="Dropped",if(and(M$1<=$I21,M$1>=$H21),if(Year($D21)=M$1,$F21*0.8,if((year($D21)+1)=M$1,$F21*0.6,$F21*0.4)) ,""),if($E21="Minors",0,if($E21="FA Contract",if(and(M$1<=$I21,M$1>=$H21),$F21,""),if($E21="YP Contract",if(M$1=$H21,500000,if(M$1=($H21+1),1000000,if(M$1=($H21+2),1500000,"")))))))) | N21: =if($E21="","",if($E21="Dropped",if(and(N$1<=$I21,N$1>=$H21),if(Year($D21)=N$1,$F21*0.8,if((year($D21)+1)=N$1,$F21*0.6,$F21*0.4)) ,""),if($E21="Minors",0,if($E21="FA Contract",if(and(N$1<=$I21,N$1>=$H21),$F21,""),if($E21="YP Contract",if(N$1=$H21,500000,if(N$1=($H21+1),1000000,if(N$1=($H21+2),1500000,"")))))))) | O21: =if($E21="","",if($E21="Dropped",if(and(O$1<=$I21,O$1>=$H21),if(Year($D21)=O$1,$F21*0.8,if((year($D21)+1)=O$1,$F21*0.6,$F21*0.4)) ,""),if($E21="Minors",0,if($E21="FA Contract",if(and(O$1<=$I21,O$1>=$H21),$F21,""),if($E21="YP Contract",if(O$1=$H21,500000,if(O$1=($H21+1),1000000,if(O$1=($H21+2),1500000,"")))))))) | P21: =if($E21="","",if($E21="Dropped",if(and(P$1<=$I21,P$1>=$H21),if(Year($D21)=P$1,$F21*0.8,if((year($D21)+1)=P$1,$F21*0.6,$F21*0.4)) ,""),if($E21="Minors",0,if($E21="FA Contract",if(and(P$1<=$I21,P$1>=$H21),$F21,""),if($E21="YP Contract",if(P$1=$H21,500000,if(P$1=($H21+1),1000000,if(P$1=($H21+2),1500000,""))))))))
A22: AJ Minter | B22: Brenden Freedman | C22: 45356 | E22: FA Contract | F22: 1500000 | G22: 2 | H22: 2024 | I22: =if(H22="","",if(or($E22="FA Contract",$E22="Dropped"),$H22+$G22-1,if($E22="YP Contract",$H22+2,if(and($E22="Minors",$G22<>"YP"),$H22+$G22-1,if(and($E22="Minors",$G22="YP"),$H22+2,""))))) -> 2025 | J22: 33100000 | K22: =if($E22="","",if($E22="Dropped",if(and(K$1<=$I22,K$1>=$H22),if(Year($D22)=K$1,$F22*0.8,if((year($D22)+1)=K$1,$F22*0.6,$F22*0.4)) ,""),if($E22="Minors",0,if($E22="FA Contract",if(and(K$1<=$I22,K$1>=$H22),$F22,""),if($E22="YP Contract",if(K$1=$H22,500000,if(K$1=($H22+1),1000000,if(K$1=($H22+2),1500000,"")))))))) -> 1500000 | L22: =if($E22="","",if($E22="Dropped",if(and(L$1<=$I22,L$1>=$H22),if(Year($D22)=L$1,$F22*0.8,if((year($D22)+1)=L$1,$F22*0.6,$F22*0.4)) ,""),if($E22="Minors",0,if($E22="FA Contract",if(and(L$1<=$I22,L$1>=$H22),$F22,""),if($E22="YP Contract",if(L$1=$H22,500000,if(L$1=($H22+1),1000000,if(L$1=($H22+2),1500000,"")))))))) | M22: =if($E22="","",if($E22="Dropped",if(and(M$1<=$I22,M$1>=$H22),if(Year($D22)=M$1,$F22*0.8,if((year($D22)+1)=M$1,$F22*0.6,$F22*0.4)) ,""),if($E22="Minors",0,if($E22="FA Contract",if(and(M$1<=$I22,M$1>=$H22),$F22,""),if($E22="YP Contract",if(M$1=$H22,500000,if(M$1=($H22+1),1000000,if(M$1=($H22+2),1500000,"")))))))) | N22: =if($E22="","",if($E22="Dropped",if(and(N$1<=$I22,N$1>=$H22),if(Year($D22)=N$1,$F22*0.8,if((year($D22)+1)=N$1,$F22*0.6,$F22*0.4)) ,""),if($E22="Minors",0,if($E22="FA Contract",if(and(N$1<=$I22,N$1>=$H22),$F22,""),if($E22="YP Contract",if(N$1=$H22,500000,if(N$1=($H22+1),1000000,if(N$1=($H22+2),1500000,"")))))))) | O22: =if($E22="","",if($E22="Dropped",if(and(O$1<=$I22,O$1>=$H22),if(Year($D22)=O$1,$F22*0.8,if((year($D22)+1)=O$1,$F22*0.6,$F22*0.4)) ,""),if($E22="Minors",0,if($E22="FA Contract",if(and(O$1<=$I22,O$1>=$H22),$F22,""),if($E22="YP Contract",if(O$1=$H22,500000,if(O$1=($H22+1),1000000,if(O$1=($H22+2),1500000,"")))))))) | P22: =if($E22="","",if($E22="Dropped",if(and(P$1<=$I22,P$1>=$H22),if(Year($D22)=P$1,$F22*0.8,if((year($D22)+1)=P$1,$F22*0.6,$F22*0.4)) ,""),if($E22="Minors",0,if($E22="FA Contract",if(and(P$1<=$I22,P$1>=$H22),$F22,""),if($E22="YP Contract",if(P$1=$H22,500000,if(P$1=($H22+1),1000000,if(P$1=($H22+2),1500000,""))))))))
A23: Alex Verdugo | B23: Brenden Freedman | C23: 45356 | E23: FA Contract | F23: 1500000 | G23: 2 | H23: 2024 | I23: =if(H23="","",if(or($E23="FA Contract",$E23="Dropped"),$H23+$G23-1,if($E23="YP Contract",$H23+2,if(and($E23="Minors",$G23<>"YP"),$H23+$G23-1,if(and($E23="Minors",$G23="YP"),$H23+2,""))))) -> 2025 | J23: 33100000 | K23: =if($E23="","",if($E23="Dropped",if(and(K$1<=$I23,K$1>=$H23),if(Year($D23)=K$1,$F23*0.8,if((year($D23)+1)=K$1,$F23*0.6,$F23*0.4)) ,""),if($E23="Minors",0,if($E23="FA Contract",if(and(K$1<=$I23,K$1>=$H23),$F23,""),if($E23="YP Contract",if(K$1=$H23,500000,if(K$1=($H23+1),1000000,if(K$1=($H23+2),1500000,"")))))))) -> 1500000 | L23: =if($E23="","",if($E23="Dropped",if(and(L$1<=$I23,L$1>=$H23),if(Year($D23)=L$1,$F23*0.8,if((year($D23)+1)=L$1,$F23*0.6,$F23*0.4)) ,""),if($E23="Minors",0,if($E23="FA Contract",if(and(L$1<=$I23,L$1>=$H23),$F23,""),if($E23="YP Contract",if(L$1=$H23,500000,if(L$1=($H23+1),1000000,if(L$1=($H23+2),1500000,"")))))))) | M23: =if($E23="","",if($E23="Dropped",if(and(M$1<=$I23,M$1>=$H23),if(Year($D23)=M$1,$F23*0.8,if((year($D23)+1)=M$1,$F23*0.6,$F23*0.4)) ,""),if($E23="Minors",0,if($E23="FA Contract",if(and(M$1<=$I23,M$1>=$H23),$F23,""),if($E23="YP Contract",if(M$1=$H23,500000,if(M$1=($H23+1),1000000,if(M$1=($H23+2),1500000,"")))))))) | N23: =if($E23="","",if($E23="Dropped",if(and(N$1<=$I23,N$1>=$H23),if(Year($D23)=N$1,$F23*0.8,if((year($D23)+1)=N$1,$F23*0.6,$F23*0.4)) ,""),if($E23="Minors",0,if($E23="FA Contract",if(and(N$1<=$I23,N$1>=$H23),$F23,""),if($E23="YP Contract",if(N$1=$H23,500000,if(N$1=($H23+1),1000000,if(N$1=($H23+2),1500000,"")))))))) | O23: =if($E23="","",if($E23="Dropped",if(and(O$1<=$I23,O$1>=$H23),if(Year($D23)=O$1,$F23*0.8,if((year($D23)+1)=O$1,$F23*0.6,$F23*0.4)) ,""),if($E23="Minors",0,if($E23="FA Contract",if(and(O$1<=$I23,O$1>=$H23),$F23,""),if($E23="YP Contract",if(O$1=$H23,500000,if(O$1=($H23+1),1000000,if(O$1=($H23+2),1500000,"")))))))) | P23: =if($E23="","",if($E23="Dropped",if(and(P$1<=$I23,P$1>=$H23),if(Year($D23)=P$1,$F23*0.8,if((year($D23)+1)=P$1,$F23*0.6,$F23*0.4)) ,""),if($E23="Minors",0,if($E23="FA Contract",if(and(P$1<=$I23,P$1>=$H23),$F23,""),if($E23="YP Contract",if(P$1=$H23,500000,if(P$1=($H23+1),1000000,if(P$1=($H23+2),1500000,""))))))))
A24: Brandon Pfadt | B24: Brenden Freedman | C24: 45343 | E24: YP Contract | F24: YP | G24: YP | H24: 2023 | I24: =if(H24="","",if(or($E24="FA Contract",$E24="Dropped"),$H24+$G24-1,if($E24="YP Contract",$H24+2,if(and($E24="Minors",$G24<>"YP"),$H24+$G24-1,if(and($E24="Minors",$G24="YP"),$H24+2,""))))) -> 2025 | J24: 33100000 | K24: =if($E24="","",if($E24="Dropped",if(and(K$1<=$I24,K$1>=$H24),if(Year($D24)=K$1,$F24*0.8,if((year($D24)+1)=K$1,$F24*0.6,$F24*0.4)) ,""),if($E24="Minors",0,if($E24="FA Contract",if(and(K$1<=$I24,K$1>=$H24),$F24,""),if($E24="YP Contract",if(K$1=$H24,500000,if(K$1=($H24+1),1000000,if(K$1=($H24+2),1500000,"")))))))) -> 1500000 | L24: =if($E24="","",if($E24="Dropped",if(and(L$1<=$I24,L$1>=$H24),if(Year($D24)=L$1,$F24*0.8,if((year($D24)+1)=L$1,$F24*0.6,$F24*0.4)) ,""),if($E24="Minors",0,if($E24="FA Contract",if(and(L$1<=$I24,L$1>=$H24),$F24,""),if($E24="YP Contract",if(L$1=$H24,500000,if(L$1=($H24+1),1000000,if(L$1=($H24+2),1500000,"")))))))) | M24: =if($E24="","",if($E24="Dropped",if(and(M$1<=$I24,M$1>=$H24),if(Year($D24)=M$1,$F24*0.8,if((year($D24)+1)=M$1,$F24*0.6,$F24*0.4)) ,""),if($E24="Minors",0,if($E24="FA Contract",if(and(M$1<=$I24,M$1>=$H24),$F24,""),if($E24="YP Contract",if(M$1=$H24,500000,if(M$1=($H24+1),1000000,if(M$1=($H24+2),1500000,"")))))))) | N24: =if($E24="","",if($E24="Dropped",if(and(N$1<=$I24,N$1>=$H24),if(Year($D24)=N$1,$F24*0.8,if((year($D24)+1)=N$1,$F24*0.6,$F24*0.4)) ,""),if($E24="Minors",0,if($E24="FA Contract",if(and(N$1<=$I24,N$1>=$H24),$F24,""),if($E24="YP Contract",if(N$1=$H24,500000,if(N$1=($H24+1),1000000,if(N$1=($H24+2),1500000,"")))))))) | O24: =if($E24="","",if($E24="Dropped",if(and(O$1<=$I24,O$1>=$H24),if(Year($D24)=O$1,$F24*0.8,if((year($D24)+1)=O$1,$F24*0.6,$F24*0.4)) ,""),if($E24="Minors",0,if($E24="FA Contract",if(and(O$1<=$I24,O$1>=$H24),$F24,""),if($E24="YP Contract",if(O$1=$H24,500000,if(O$1=($H24+1),1000000,if(O$1=($H24+2),1500000,"")))))))) | P24: =if($E24="","",if($E24="Dropped",if(and(P$1<=$I24,P$1>=$H24),if(Year($D24)=P$1,$F24*0.8,if((year($D24)+1)=P$1,$F24*0.6,$F24*0.4)) ,""),if($E24="Minors",0,if($E24="FA Contract",if(and(P$1<=$I24,P$1>=$H24),$F24,""),if($E24="YP Contract",if(P$1=$H24,500000,if(P$1=($H24+1),1000000,if(P$1=($H24+2),1500000,""))))))))
A25: Ezequiel Tovar | B25: Brenden Freedman | C25: 45343 | E25: YP Contract | F25: YP | G25: YP | H25: 2023 | I25: =if(H25="","",if(or($E25="FA Contract",$E25="Dropped"),$H25+$G25-1,if($E25="YP Contract",$H25+2,if(and($E25="Minors",$G25<>"YP"),$H25+$G25-1,if(and($E25="Minors",$G25="YP"),$H25+2,""))))) -> 2025 | J25: 33100000 | K25: =if($E25="","",if($E25="Dropped",if(and(K$1<=$I25,K$1>=$H25),if(Year($D25)=K$1,$F25*0.8,if((year($D25)+1)=K$1,$F25*0.6,$F25*0.4)) ,""),if($E25="Minors",0,if($E25="FA Contract",if(and(K$1<=$I25,K$1>=$H25),$F25,""),if($E25="YP Contract",if(K$1=$H25,500000,if(K$1=($H25+1),1000000,if(K$1=($H25+2),1500000,"")))))))) -> 1500000 | L25: =if($E25="","",if($E25="Dropped",if(and(L$1<=$I25,L$1>=$H25),if(Year($D25)=L$1,$F25*0.8,if((year($D25)+1)=L$1,$F25*0.6,$F25*0.4)) ,""),if($E25="Minors",0,if($E25="FA Contract",if(and(L$1<=$I25,L$1>=$H25),$F25,""),if($E25="YP Contract",if(L$1=$H25,500000,if(L$1=($H25+1),1000000,if(L$1=($H25+2),1500000,"")))))))) | M25: =if($E25="","",if($E25="Dropped",if(and(M$1<=$I25,M$1>=$H25),if(Year($D25)=M$1,$F25*0.8,if((year($D25)+1)=M$1,$F25*0.6,$F25*0.4)) ,""),if($E25="Minors",0,if($E25="FA Contract",if(and(M$1<=$I25,M$1>=$H25),$F25,""),if($E25="YP Contract",if(M$1=$H25,500000,if(M$1=($H25+1),1000000,if(M$1=($H25+2),1500000,"")))))))) | N25: =if($E25="","",if($E25="Dropped",if(and(N$1<=$I25,N$1>=$H25),if(Year($D25)=N$1,$F25*0.8,if((year($D25)+1)=N$1,$F25*0.6,$F25*0.4)) ,""),if($E25="Minors",0,if($E25="FA Contract",if(and(N$1<=$I25,N$1>=$H25),$F25,""),if($E25="YP Contract",if(N$1=$H25,500000,if(N$1=($H25+1),1000000,if(N$1=($H25+2),1500000,"")))))))) | O25: =if($E25="","",if($E25="Dropped",if(and(O$1<=$I25,O$1>=$H25),if(Year($D25)=O$1,$F25*0.8,if((year($D25)+1)=O$1,$F25*0.6,$F25*0.4)) ,""),if($E25="Minors",0,if($E25="FA Contract",if(and(O$1<=$I25,O$1>=$H25),$F25,""),if($E25="YP Contract",if(O$1=$H25,500000,if(O$1=($H25+1),1000000,if(O$1=($H25+2),1500000,"")))))))) | P25: =if($E25="","",if($E25="Dropped",if(and(P$1<=$I25,P$1>=$H25),if(Year($D25)=P$1,$F25*0.8,if((year($D25)+1)=P$1,$F25*0.6,$F25*0.4)) ,""),if($E25="Minors",0,if($E25="FA Contract",if(and(P$1<=$I25,P$1>=$H25),$F25,""),if($E25="YP Contract",if(P$1=$H25,500000,if(P$1=($H25+1),1000000,if(P$1=($H25+2),1500000,""))))))))
A26: Reese Olson | B26: Brenden Freedman | C26: 45343 | E26: YP Contract | F26: YP | G26: YP | H26: 2023 | I26: =if(H26="","",if(or($E26="FA Contract",$E26="Dropped"),$H26+$G26-1,if($E26="YP Contract",$H26+2,if(and($E26="Minors",$G26<>"YP"),$H26+$G26-1,if(and($E26="Minors",$G26="YP"),$H26+2,""))))) -> 2025 | J26: 33100000 | K26: =if($E26="","",if($E26="Dropped",if(and(K$1<=$I26,K$1>=$H26),if(Year($D26)=K$1,$F26*0.8,if((year($D26)+1)=K$1,$F26*0.6,$F26*0.4)) ,""),if($E26="Minors",0,if($E26="FA Contract",if(and(K$1<=$I26,K$1>=$H26),$F26,""),if($E26="YP Contract",if(K$1=$H26,500000,if(K$1=($H26+1),1000000,if(K$1=($H26+2),1500000,"")))))))) -> 1500000 | L26: =if($E26="","",if($E26="Dropped",if(and(L$1<=$I26,L$1>=$H26),if(Year($D26)=L$1,$F26*0.8,if((year($D26)+1)=L$1,$F26*0.6,$F26*0.4)) ,""),if($E26="Minors",0,if($E26="FA Contract",if(and(L$1<=$I26,L$1>=$H26),$F26,""),if($E26="YP Contract",if(L$1=$H26,500000,if(L$1=($H26+1),1000000,if(L$1=($H26+2),1500000,"")))))))) | M26: =if($E26="","",if($E26="Dropped",if(and(M$1<=$I26,M$1>=$H26),if(Year($D26)=M$1,$F26*0.8,if((year($D26)+1)=M$1,$F26*0.6,$F26*0.4)) ,""),if($E26="Minors",0,if($E26="FA Contract",if(and(M$1<=$I26,M$1>=$H26),$F26,""),if($E26="YP Contract",if(M$1=$H26,500000,if(M$1=($H26+1),1000000,if(M$1=($H26+2),1500000,"")))))))) | N26: =if($E26="","",if($E26="Dropped",if(and(N$1<=$I26,N$1>=$H26),if(Year($D26)=N$1,$F26*0.8,if((year($D26)+1)=N$1,$F26*0.6,$F26*0.4)) ,""),if($E26="Minors",0,if($E26="FA Contract",if(and(N$1<=$I26,N$1>=$H26),$F26,""),if($E26="YP Contract",if(N$1=$H26,500000,if(N$1=($H26+1),1000000,if(N$1=($H26+2),1500000,"")))))))) | O26: =if($E26="","",if($E26="Dropped",if(and(O$1<=$I26,O$1>=$H26),if(Year($D26)=O$1,$F26*0.8,if((year($D26)+1)=O$1,$F26*0.6,$F26*0.4)) ,""),if($E26="Minors",0,if($E26="FA Contract",if(and(O$1<=$I26,O$1>=$H26),$F26,""),if($E26="YP Contract",if(O$1=$H26,500000,if(O$1=($H26+1),1000000,if(O$1=($H26+2),1500000,"")))))))) | P26: =if($E26="","",if($E26="Dropped",if(and(P$1<=$I26,P$1>=$H26),if(Year($D26)=P$1,$F26*0.8,if((year($D26)+1)=P$1,$F26*0.6,$F26*0.4)) ,""),if($E26="Minors",0,if($E26="FA Contract",if(and(P$1<=$I26,P$1>=$H26),$F26,""),if($E26="YP Contract",if(P$1=$H26,500000,if(P$1=($H26+1),1000000,if(P$1=($H26+2),1500000,""))))))))
A27: Gavin Stone | B27: Brenden Freedman | C27: 45346 | E27: YP Contract | F27: YP | G27: YP | H27: 2024 | I27: =if(H27="","",if(or($E27="FA Contract",$E27="Dropped"),$H27+$G27-1,if($E27="YP Contract",$H27+2,if(and($E27="Minors",$G27<>"YP"),$H27+$G27-1,if(and($E27="Minors",$G27="YP"),$H27+2,""))))) -> 2026 | J27: 33100000 | K27: =if($E27="","",if($E27="Dropped",if(and(K$1<=$I27,K$1>=$H27),if(Year($D27)=K$1,$F27*0.8,if((year($D27)+1)=K$1,$F27*0.6,$F27*0.4)) ,""),if($E27="Minors",0,if($E27="FA Contract",if(and(K$1<=$I27,K$1>=$H27),$F27,""),if($E27="YP Contract",if(K$1=$H27,500000,if(K$1=($H27+1),1000000,if(K$1=($H27+2),1500000,"")))))))) -> 1000000 | L27: =if($E27="","",if($E27="Dropped",if(and(L$1<=$I27,L$1>=$H27),if(Year($D27)=L$1,$F27*0.8,if((year($D27)+1)=L$1,$F27*0.6,$F27*0.4)) ,""),if($E27="Minors",0,if($E27="FA Contract",if(and(L$1<=$I27,L$1>=$H27),$F27,""),if($E27="YP Contract",if(L$1=$H27,500000,if(L$1=($H27+1),1000000,if(L$1=($H27+2),1500000,"")))))))) -> 1500000 | M27: =if($E27="","",if($E27="Dropped",if(and(M$1<=$I27,M$1>=$H27),if(Year($D27)=M$1,$F27*0.8,if((year($D27)+1)=M$1,$F27*0.6,$F27*0.4)) ,""),if($E27="Minors",0,if($E27="FA Contract",if(and(M$1<=$I27,M$1>=$H27),$F27,""),if($E27="YP Contract",if(M$1=$H27,500000,if(M$1=($H27+1),1000000,if(M$1=($H27+2),1500000,"")))))))) | N27: =if($E27="","",if($E27="Dropped",if(and(N$1<=$I27,N$1>=$H27),if(Year($D27)=N$1,$F27*0.8,if((year($D27)+1)=N$1,$F27*0.6,$F27*0.4)) ,""),if($E27="Minors",0,if($E27="FA Contract",if(and(N$1<=$I27,N$1>=$H27),$F27,""),if($E27="YP Contract",if(N$1=$H27,500000,if(N$1=($H27+1),1000000,if(N$1=($H27+2),1500000,"")))))))) | O27: =if($E27="","",if($E27="Dropped",if(and(O$1<=$I27,O$1>=$H27),if(Year($D27)=O$1,$F27*0.8,if((year($D27)+1)=O$1,$F27*0.6,$F27*0.4)) ,""),if($E27="Minors",0,if($E27="FA Contract",if(and(O$1<=$I27,O$1>=$H27),$F27,""),if($E27="YP Contract",if(O$1=$H27,500000,if(O$1=($H27+1),1000000,if(O$1=($H27+2),1500000,"")))))))) | P27: =if($E27="","",if($E27="Dropped",if(and(P$1<=$I27,P$1>=$H27),if(Year($D27)=P$1,$F27*0.8,if((year($D27)+1)=P$1,$F27*0.6,$F27*0.4)) ,""),if($E27="Minors",0,if($E27="FA Contract",if(and(P$1<=$I27,P$1>=$H27),$F27,""),if($E27="YP Contract",if(P$1=$H27,500000,if(P$1=($H27+1),1000000,if(P$1=($H27+2),1500000,""))))))))
A28: Ivan Herrera | B28: Brenden Freedman | C28: 45350 | E28: YP Contract | F28: YP | G28: YP | H28: 2024 | I28: =if(H28="","",if(or($E28="FA Contract",$E28="Dropped"),$H28+$G28-1,if($E28="YP Contract",$H28+2,if(and($E28="Minors",$G28<>"YP"),$H28+$G28-1,if(and($E28="Minors",$G28="YP"),$H28+2,""))))) -> 2026 | J28: 33100000 | K28: =if($E28="","",if($E28="Dropped",if(and(K$1<=$I28,K$1>=$H28),if(Year($D28)=K$1,$F28*0.8,if((year($D28)+1)=K$1,$F28*0.6,$F28*0.4)) ,""),if($E28="Minors",0,if($E28="FA Contract",if(and(K$1<=$I28,K$1>=$H28),$F28,""),if($E28="YP Contract",if(K$1=$H28,500000,if(K$1=($H28+1),1000000,if(K$1=($H28+2),1500000,"")))))))) -> 1000000 | L28: =if($E28="","",if($E28="Dropped",if(and(L$1<=$I28,L$1>=$H28),if(Year($D28)=L$1,$F28*0.8,if((year($D28)+1)=L$1,$F28*0.6,$F28*0.4)) ,""),if($E28="Minors",0,if($E28="FA Contract",if(and(L$1<=$I28,L$1>=$H28),$F28,""),if($E28="YP Contract",if(L$1=$H28,500000,if(L$1=($H28+1),1000000,if(L$1=($H28+2),1500000,"")))))))) -> 1500000 | M28: =if($E28="","",if($E28="Dropped",if(and(M$1<=$I28,M$1>=$H28),if(Year($D28)=M$1,$F28*0.8,if((year($D28)+1)=M$1,$F28*0.6,$F28*0.4)) ,""),if($E28="Minors",0,if($E28="FA Contract",if(and(M$1<=$I28,M$1>=$H28),$F28,""),if($E28="YP Contract",if(M$1=$H28,500000,if(M$1=($H28+1),1000000,if(M$1=($H28+2),1500000,"")))))))) | N28: =if($E28="","",if($E28="Dropped",if(and(N$1<=$I28,N$1>=$H28),if(Year($D28)=N$1,$F28*0.8,if((year($D28)+1)=N$1,$F28*0.6,$F28*0.4)) ,""),if($E28="Minors",0,if($E28="FA Contract",if(and(N$1<=$I28,N$1>=$H28),$F28,""),if($E28="YP Contract",if(N$1=$H28,500000,if(N$1=($H28+1),1000000,if(N$1=($H28+2),1500000,"")))))))) | O28: =if($E28="","",if($E28="Dropped",if(and(O$1<=$I28,O$1>=$H28),if(Year($D28)=O$1,$F28*0.8,if((year($D28)+1)=O$1,$F28*0.6,$F28*0.4)) ,""),if($E28="Minors",0,if($E28="FA Contract",if(and(O$1<=$I28,O$1>=$H28),$F28,""),if($E28="YP Contract",if(O$1=$H28,500000,if(O$1=($H28+1),1000000,if(O$1=($H28+2),1500000,"")))))))) | P28: =if($E28="","",if($E28="Dropped",if(and(P$1<=$I28,P$1>=$H28),if(Year($D28)=P$1,$F28*0.8,if((year($D28)+1)=P$1,$F28*0.6,$F28*0.4)) ,""),if($E28="Minors",0,if($E28="FA Contract",if(and(P$1<=$I28,P$1>=$H28),$F28,""),if($E28="YP Contract",if(P$1=$H28,500000,if(P$1=($H28+1),1000000,if(P$1=($H28+2),1500000,""))))))))
A29: Jackson Holliday | B29: Brenden Freedman | C29: 45343 | E29: YP Contract | F29: YP | G29: YP | H29: 2024 | I29: =if(H29="","",if(or($E29="FA Contract",$E29="Dropped"),$H29+$G29-1,if($E29="YP Contract",$H29+2,if(and($E29="Minors",$G29<>"YP"),$H29+$G29-1,if(and($E29="Minors",$G29="YP"),$H29+2,""))))) -> 2026 | J29: 33100000 | K29: =if($E29="","",if($E29="Dropped",if(and(K$1<=$I29,K$1>=$H29),if(Year($D29)=K$1,$F29*0.8,if((year($D29)+1)=K$1,$F29*0.6,$F29*0.4)) ,""),if($E29="Minors",0,if($E29="FA Contract",if(and(K$1<=$I29,K$1>=$H29),$F29,""),if($E29="YP Contract",if(K$1=$H29,500000,if(K$1=($H29+1),1000000,if(K$1=($H29+2),1500000,"")))))))) -> 1000000 | L29: =if($E29="","",if($E29="Dropped",if(and(L$1<=$I29,L$1>=$H29),if(Year($D29)=L$1,$F29*0.8,if((year($D29)+1)=L$1,$F29*0.6,$F29*0.4)) ,""),if($E29="Minors",0,if($E29="FA Contract",if(and(L$1<=$I29,L$1>=$H29),$F29,""),if($E29="YP Contract",if(L$1=$H29,500000,if(L$1=($H29+1),1000000,if(L$1=($H29+2),1500000,"")))))))) -> 1500000 | M29: =if($E29="","",if($E29="Dropped",if(and(M$1<=$I29,M$1>=$H29),if(Year($D29)=M$1,$F29*0.8,if((year($D29)+1)=M$1,$F29*0.6,$F29*0.4)) ,""),if($E29="Minors",0,if($E29="FA Contract",if(and(M$1<=$I29,M$1>=$H29),$F29,""),if($E29="YP Contract",if(M$1=$H29,500000,if(M$1=($H29+1),1000000,if(M$1=($H29+2),1500000,"")))))))) | N29: =if($E29="","",if($E29="Dropped",if(and(N$1<=$I29,N$1>=$H29),if(Year($D29)=N$1,$F29*0.8,if((year($D29)+1)=N$1,$F29*0.6,$F29*0.4)) ,""),if($E29="Minors",0,if($E29="FA Contract",if(and(N$1<=$I29,N$1>=$H29),$F29,""),if($E29="YP Contract",if(N$1=$H29,500000,if(N$1=($H29+1),1000000,if(N$1=($H29+2),1500000,"")))))))) | O29: =if($E29="","",if($E29="Dropped",if(and(O$1<=$I29,O$1>=$H29),if(Year($D29)=O$1,$F29*0.8,if((year($D29)+1)=O$1,$F29*0.6,$F29*0.4)) ,""),if($E29="Minors",0,if($E29="FA Contract",if(and(O$1<=$I29,O$1>=$H29),$F29,""),if($E29="YP Contract",if(O$1=$H29,500000,if(O$1=($H29+1),1000000,if(O$1=($H29+2),1500000,"")))))))) | P29: =if($E29="","",if($E29="Dropped",if(and(P$1<=$I29,P$1>=$H29),if(Year($D29)=P$1,$F29*0.8,if((year($D29)+1)=P$1,$F29*0.6,$F29*0.4)) ,""),if($E29="Minors",0,if($E29="FA Contract",if(and(P$1<=$I29,P$1>=$H29),$F29,""),if($E29="YP Contract",if(P$1=$H29,500000,if(P$1=($H29+1),1000000,if(P$1=($H29+2),1500000,""))))))))
A30: Jose Siri | B30: Brenden Freedman | C30: 45356 | E30: FA Contract | F30: 1000000 | G30: 2 | H30: 2024 | I30: =if(H30="","",if(or($E30="FA Contract",$E30="Dropped"),$H30+$G30-1,if($E30="YP Contract",$H30+2,if(and($E30="Minors",$G30<>"YP"),$H30+$G30-1,if(and($E30="Minors",$G30="YP"),$H30+2,""))))) -> 2025 | J30: 33100000 | K30: =if($E30="","",if($E30="Dropped",if(and(K$1<=$I30,K$1>=$H30),if(Year($D30)=K$1,$F30*0.8,if((year($D30)+1)=K$1,$F30*0.6,$F30*0.4)) ,""),if($E30="Minors",0,if($E30="FA Contract",if(and(K$1<=$I30,K$1>=$H30),$F30,""),if($E30="YP Contract",if(K$1=$H30,500000,if(K$1=($H30+1),1000000,if(K$1=($H30+2),1500000,"")))))))) -> 1000000 | L30: =if($E30="","",if($E30="Dropped",if(and(L$1<=$I30,L$1>=$H30),if(Year($D30)=L$1,$F30*0.8,if((year($D30)+1)=L$1,$F30*0.6,$F30*0.4)) ,""),if($E30="Minors",0,if($E30="FA Contract",if(and(L$1<=$I30,L$1>=$H30),$F30,""),if($E30="YP Contract",if(L$1=$H30,500000,if(L$1=($H30+1),1000000,if(L$1=($H30+2),1500000,"")))))))) | M30: =if($E30="","",if($E30="Dropped",if(and(M$1<=$I30,M$1>=$H30),if(Year($D30)=M$1,$F30*0.8,if((year($D30)+1)=M$1,$F30*0.6,$F30*0.4)) ,""),if($E30="Minors",0,if($E30="FA Contract",if(and(M$1<=$I30,M$1>=$H30),$F30,""),if($E30="YP Contract",if(M$1=$H30,500000,if(M$1=($H30+1),1000000,if(M$1=($H30+2),1500000,"")))))))) | N30: =if($E30="","",if($E30="Dropped",if(and(N$1<=$I30,N$1>=$H30),if(Year($D30)=N$1,$F30*0.8,if((year($D30)+1)=N$1,$F30*0.6,$F30*0.4)) ,""),if($E30="Minors",0,if($E30="FA Contract",if(and(N$1<=$I30,N$1>=$H30),$F30,""),if($E30="YP Contract",if(N$1=$H30,500000,if(N$1=($H30+1),1000000,if(N$1=($H30+2),1500000,"")))))))) | O30: =if($E30="","",if($E30="Dropped",if(and(O$1<=$I30,O$1>=$H30),if(Year($D30)=O$1,$F30*0.8,if((year($D30)+1)=O$1,$F30*0.6,$F30*0.4)) ,""),if($E30="Minors",0,if($E30="FA Contract",if(and(O$1<=$I30,O$1>=$H30),$F30,""),if($E30="YP Contract",if(O$1=$H30,500000,if(O$1=($H30+1),1000000,if(O$1=($H30+2),1500000,"")))))))) | P30: =if($E30="","",if($E30="Dropped",if(and(P$1<=$I30,P$1>=$H30),if(Year($D30)=P$1,$F30*0.8,if((year($D30)+1)=P$1,$F30*0.6,$F30*0.4)) ,""),if($E30="Minors",0,if($E30="FA Contract",if(and(P$1<=$I30,P$1>=$H30),$F30,""),if($E30="YP Contract",if(P$1=$H30,500000,if(P$1=($H30+1),1000000,if(P$1=($H30+2),1500000,""))))))))
A31: Kerbert Ruiz | B31: Brenden Freedman | C31: 45356 | E31: FA Contract | F31: 1000000 | G31: 2 | H31: 2024 | I31: =if(H31="","",if(or($E31="FA Contract",$E31="Dropped"),$H31+$G31-1,if($E31="YP Contract",$H31+2,if(and($E31="Minors",$G31<>"YP"),$H31+$G31-1,if(and($E31="Minors",$G31="YP"),$H31+2,""))))) -> 2025 | J31: 33100000 | K31: =if($E31="","",if($E31="Dropped",if(and(K$1<=$I31,K$1>=$H31),if(Year($D31)=K$1,$F31*0.8,if((year($D31)+1)=K$1,$F31*0.6,$F31*0.4)) ,""),if($E31="Minors",0,if($E31="FA Contract",if(and(K$1<=$I31,K$1>=$H31),$F31,""),if($E31="YP Contract",if(K$1=$H31,500000,if(K$1=($H31+1),1000000,if(K$1=($H31+2),1500000,"")))))))) -> 1000000 | L31: =if($E31="","",if($E31="Dropped",if(and(L$1<=$I31,L$1>=$H31),if(Year($D31)=L$1,$F31*0.8,if((year($D31)+1)=L$1,$F31*0.6,$F31*0.4)) ,""),if($E31="Minors",0,if($E31="FA Contract",if(and(L$1<=$I31,L$1>=$H31),$F31,""),if($E31="YP Contract",if(L$1=$H31,500000,if(L$1=($H31+1),1000000,if(L$1=($H31+2),1500000,"")))))))) | M31: =if($E31="","",if($E31="Dropped",if(and(M$1<=$I31,M$1>=$H31),if(Year($D31)=M$1,$F31*0.8,if((year($D31)+1)=M$1,$F31*0.6,$F31*0.4)) ,""),if($E31="Minors",0,if($E31="FA Contract",if(and(M$1<=$I31,M$1>=$H31),$F31,""),if($E31="YP Contract",if(M$1=$H31,500000,if(M$1=($H31+1),1000000,if(M$1=($H31+2),1500000,"")))))))) | N31: =if($E31="","",if($E31="Dropped",if(and(N$1<=$I31,N$1>=$H31),if(Year($D31)=N$1,$F31*0.8,if((year($D31)+1)=N$1,$F31*0.6,$F31*0.4)) ,""),if($E31="Minors",0,if($E31="FA Contract",if(and(N$1<=$I31,N$1>=$H31),$F31,""),if($E31="YP Contract",if(N$1=$H31,500000,if(N$1=($H31+1),1000000,if(N$1=($H31+2),1500000,"")))))))) | O31: =if($E31="","",if($E31="Dropped",if(and(O$1<=$I31,O$1>=$H31),if(Year($D31)=O$1,$F31*0.8,if((year($D31)+1)=O$1,$F31*0.6,$F31*0.4)) ,""),if($E31="Minors",0,if($E31="FA Contract",if(and(O$1<=$I31,O$1>=$H31),$F31,""),if($E31="YP Contract",if(O$1=$H31,500000,if(O$1=($H31+1),1000000,if(O$1=($H31+2),1500000,"")))))))) | P31: =if($E31="","",if($E31="Dropped",if(and(P$1<=$I31,P$1>=$H31),if(Year($D31)=P$1,$F31*0.8,if((year($D31)+1)=P$1,$F31*0.6,$F31*0.4)) ,""),if($E31="Minors",0,if($E31="FA Contract",if(and(P$1<=$I31,P$1>=$H31),$F31,""),if($E31="YP Contract",if(P$1=$H31,500000,if(P$1=($H31+1),1000000,if(P$1=($H31+2),1500000,""))))))))
A32: Chase Burns | B32: Brenden Freedman | C32: 45684 | E32: YP Contract | F32: YP | G32: YP | H32: 2025 | I32: =if(H32="","",if(or($E32="FA Contract",$E32="Dropped"),$H32+$G32-1,if($E32="YP Contract",$H32+2,if(and($E32="Minors",$G32<>"YP"),$H32+$G32-1,if(and($E32="Minors",$G32="YP"),$H32+2,""))))) -> 2027 | J32: 33100000 | K32: =if($E32="","",if($E32="Dropped",if(and(K$1<=$I32,K$1>=$H32),if(Year($D32)=K$1,$F32*0.8,if((year($D32)+1)=K$1,$F32*0.6,$F32*0.4)) ,""),if($E32="Minors",0,if($E32="FA Contract",if(and(K$1<=$I32,K$1>=$H32),$F32,""),if($E32="YP Contract",if(K$1=$H32,500000,if(K$1=($H32+1),1000000,if(K$1=($H32+2),1500000,"")))))))) -> 500000 | L32: =if($E32="","",if($E32="Dropped",if(and(L$1<=$I32,L$1>=$H32),if(Year($D32)=L$1,$F32*0.8,if((year($D32)+1)=L$1,$F32*0.6,$F32*0.4)) ,""),if($E32="Minors",0,if($E32="FA Contract",if(and(L$1<=$I32,L$1>=$H32),$F32,""),if($E32="YP Contract",if(L$1=$H32,500000,if(L$1=($H32+1),1000000,if(L$1=($H32+2),1500000,"")))))))) -> 1000000 | M32: =if($E32="","",if($E32="Dropped",if(and(M$1<=$I32,M$1>=$H32),if(Year($D32)=M$1,$F32*0.8,if((year($D32)+1)=M$1,$F32*0.6,$F32*0.4)) ,""),if($E32="Minors",0,if($E32="FA Contract",if(and(M$1<=$I32,M$1>=$H32),$F32,""),if($E32="YP Contract",if(M$1=$H32,500000,if(M$1=($H32+1),1000000,if(M$1=($H32+2),1500000,"")))))))) -> 1500000 | N32: =if($E32="","",if($E32="Dropped",if(and(N$1<=$I32,N$1>=$H32),if(Year($D32)=N$1,$F32*0.8,if((year($D32)+1)=N$1,$F32*0.6,$F32*0.4)) ,""),if($E32="Minors",0,if($E32="FA Contract",if(and(N$1<=$I32,N$1>=$H32),$F32,""),if($E32="YP Contract",if(N$1=$H32,500000,if(N$1=($H32+1),1000000,if(N$1=($H32+2),1500000,"")))))))) | O32: =if($E32="","",if($E32="Dropped",if(and(O$1<=$I32,O$1>=$H32),if(Year($D32)=O$1,$F32*0.8,if((year($D32)+1)=O$1,$F32*0.6,$F32*0.4)) ,""),if($E32="Minors",0,if($E32="FA Contract",if(and(O$1<=$I32,O$1>=$H32),$F32,""),if($E32="YP Contract",if(O$1=$H32,500000,if(O$1=($H32+1),1000000,if(O$1=($H32+2),1500000,"")))))))) | P32: =if($E32="","",if($E32="Dropped",if(and(P$1<=$I32,P$1>=$H32),if(Year($D32)=P$1,$F32*0.8,if((year($D32)+1)=P$1,$F32*0.6,$F32*0.4)) ,""),if($E32="Minors",0,if($E32="FA Contract",if(and(P$1<=$I32,P$1>=$H32),$F32,""),if($E32="YP Contract",if(P$1=$H32,500000,if(P$1=($H32+1),1000000,if(P$1=($H32+2),1500000,""))))))))
A33: Colby Thomas | B33: Brenden Freedman | C33: 45698 | E33: YP Contract | F33: YP | G33: YP | H33: 2025 | I33: =if(H33="","",if(or($E33="FA Contract",$E33="Dropped"),$H33+$G33-1,if($E33="YP Contract",$H33+2,if(and($E33="Minors",$G33<>"YP"),$H33+$G33-1,if(and($E33="Minors",$G33="YP"),$H33+2,""))))) -> 2027 | J33: 33100000 | K33: =if($E33="","",if($E33="Dropped",if(and(K$1<=$I33,K$1>=$H33),if(Year($D33)=K$1,$F33*0.8,if((year($D33)+1)=K$1,$F33*0.6,$F33*0.4)) ,""),if($E33="Minors",0,if($E33="FA Contract",if(and(K$1<=$I33,K$1>=$H33),$F33,""),if($E33="YP Contract",if(K$1=$H33,500000,if(K$1=($H33+1),1000000,if(K$1=($H33+2),1500000,"")))))))) -> 500000 | L33: =if($E33="","",if($E33="Dropped",if(and(L$1<=$I33,L$1>=$H33),if(Year($D33)=L$1,$F33*0.8,if((year($D33)+1)=L$1,$F33*0.6,$F33*0.4)) ,""),if($E33="Minors",0,if($E33="FA Contract",if(and(L$1<=$I33,L$1>=$H33),$F33,""),if($E33="YP Contract",if(L$1=$H33,500000,if(L$1=($H33+1),1000000,if(L$1=($H33+2),1500000,"")))))))) -> 1000000 | M33: =if($E33="","",if($E33="Dropped",if(and(M$1<=$I33,M$1>=$H33),if(Year($D33)=M$1,$F33*0.8,if((year($D33)+1)=M$1,$F33*0.6,$F33*0.4)) ,""),if($E33="Minors",0,if($E33="FA Contract",if(and(M$1<=$I33,M$1>=$H33),$F33,""),if($E33="YP Contract",if(M$1=$H33,500000,if(M$1=($H33+1),1000000,if(M$1=($H33+2),1500000,"")))))))) -> 1500000 | N33: =if($E33="","",if($E33="Dropped",if(and(N$1<=$I33,N$1>=$H33),if(Year($D33)=N$1,$F33*0.8,if((year($D33)+1)=N$1,$F33*0.6,$F33*0.4)) ,""),if($E33="Minors",0,if($E33="FA Contract",if(and(N$1<=$I33,N$1>=$H33),$F33,""),if($E33="YP Contract",if(N$1=$H33,500000,if(N$1=($H33+1),1000000,if(N$1=($H33+2),1500000,"")))))))) | O33: =if($E33="","",if($E33="Dropped",if(and(O$1<=$I33,O$1>=$H33),if(Year($D33)=O$1,$F33*0.8,if((year($D33)+1)=O$1,$F33*0.6,$F33*0.4)) ,""),if($E33="Minors",0,if($E33="FA Contract",if(and(O$1<=$I33,O$1>=$H33),$F33,""),if($E33="YP Contract",if(O$1=$H33,500000,if(O$1=($H33+1),1000000,if(O$1=($H33+2),1500000,"")))))))) | P33: =if($E33="","",if($E33="Dropped",if(and(P$1<=$I33,P$1>=$H33),if(Year($D33)=P$1,$F33*0.8,if((year($D33)+1)=P$1,$F33*0.6,$F33*0.4)) ,""),if($E33="Minors",0,if($E33="FA Contract",if(and(P$1<=$I33,P$1>=$H33),$F33,""),if($E33="YP Contract",if(P$1=$H33,500000,if(P$1=($H33+1),1000000,if(P$1=($H33+2),1500000,""))))))))
